Workbook

Sheet backend
A1: Production Section | E1: Sells Section | I1: Names
A2: Product Name | B2: Amount | C2: Transfer | E2: Product Name | F2: Amount | G2: Main Name | H2: Transfer | I2: burger 11 | J2: humam
A3: فلر 26 عادي | B3: 6139 | C3: =SUMIF(productionSection[Product Name],'كشف الانتاج'!C8,productionSection[Amount]) -> 40704 | E3: كنتاكي | F3: 47344 | G3: ='كشف الانتاج'!C8 -> كنتاكي | H3: =SUMIF(sells[Product Name],sells[[#This Row],[Main Name]],sells[Amount]) -> 47344 | I3: بركر 11 | J3: همام مشرح | K3: كنتاكي | L3: 40520 | M3: =SUMIF($K$3:$K$30,sells[[#This Row],[Main Name]],$L$3:$L$30) -> 40520 | N3: كنتاكي | O3: =M3-sells[[#This Row],[Transfer]] -> -6824
A4: بركر 14 عادي | B4: 2060 | C4: =SUMIF(productionSection[Product Name],'كشف الانتاج'!C9,productionSection[Amount]) -> 0 | E4: بركر 14 عادي | F4: 6806 | G4: ='كشف الانتاج'!C9 -> كنتاكي اسمر | H4: =SUMIF(sells[Product Name],sells[[#This Row],[Main Name]],sells[Amount]) -> 0 | I4: بركر 11 لحم | J4: همام كرنشي | K4: بركر 14 عادي | L4: 6098 | M4: =SUMIF($K$3:$K$30,sells[[#This Row],[Main Name]],$L$3:$L$30) -> 400 | N4: كنتاكي اسمر | O4: =M4-sells[[#This Row],[Transfer]] -> 400
A5: بركر 14 عادي | B5: 4883 | C5: =SUMIF(productionSection[Product Name],'كشف الانتاج'!C10,productionSection[Amount]) -> 6943 | E5: بركر 14 بوليش | F5: 6192 | G5: ='كشف الانتاج'!C10 -> بركر 14 عادي | H5: =SUMIF(sells[Product Name],sells[[#This Row],[Main Name]],sells[Amount]) -> 6806 | I5: بركر 11 سمسم | K5: بركر 14 بوليش | L5: 6378 | M5: =SUMIF($K$3:$K$30,sells[[#This Row],[Main Name]],$L$3:$L$30) -> 6098 | N5: بركر 14 عادي | O5: =M5-sells[[#This Row],[Transfer]] -> -708
A6: فلر 26 بوليش | B6: 3276 | C6: =SUMIF(productionSection[Product Name],'كشف الانتاج'!C11,productionSection[Amount]) -> 6308 | E6: بركر 14 بطاطا | F6: 1570 | G6: ='كشف الانتاج'!C11 -> بركر 14 بوليش | H6: =SUMIF(sells[Product Name],sells[[#This Row],[Main Name]],sells[Amount]) -> 6192 | K6: بركر 14 بطاطا | L6: 1258 | M6: =SUMIF($K$3:$K$30,sells[[#This Row],[Main Name]],$L$3:$L$30) -> 6378 | N6: بركر 14 بوليش | O6: =M6-sells[[#This Row],[Transfer]] -> 186
A7: بركر 14 بوليش | B7: 1018 | C7: =SUMIF(productionSection[Product Name],'كشف الانتاج'!C12,productionSection[Amount]) -> 1680 | E7: بركر 13 عادي | F7: 240 | G7: ='كشف الانتاج'!C12 -> بركر 14 بطاطا | H7: =SUMIF(sells[Product Name],sells[[#This Row],[Main Name]],sells[Amount]) -> 1570 | K7: بركر 13 عادي | L7: 256 | M7: =SUMIF($K$3:$K$30,sells[[#This Row],[Main Name]],$L$3:$L$30) -> 1258 | N7: بركر 14 بطاطا | O7: =M7-sells[[#This Row],[Transfer]] -> -312
A8: بركر 14 بوليش | B8: 5290 | C8: =SUMIF(productionSection[Product Name],'كشف الانتاج'!C13,productionSection[Amount]) -> 1062 | E8: بركر 13 بوليش | F8: 576 | G8: ='كشف الانتاج'!C13 -> بركر 13 بطاطا | H8: =SUMIF(sells[Product Name],sells[[#This Row],[Main Name]],sells[Amount]) -> 1074 | K8: بركر 13 بوليش | L8: 694 | M8: =SUMIF($K$3:$K$30,sells[[#This Row],[Main Name]],$L$3:$L$30) -> 1198 | N8: بركر 13 بطاطا | O8: =M8-sells[[#This Row],[Transfer]] -> 124
A9: فلر 26 سميد | B9: 1456 | C9: =SUMIF(productionSection[Product Name],'كشف الانتاج'!C14,productionSection[Amount]) -> 860 | E9: بركر 13 بطاطا | F9: 1074 | G9: ='كشف الانتاج'!C14 -> بركر 13 بوليش | H9: =SUMIF(sells[Product Name],sells[[#This Row],[Main Name]],sells[Amount]) -> 576 | K9: بركر 13 بطاطا | L9: 1198 | M9: =SUMIF($K$3:$K$30,sells[[#This Row],[Main Name]],$L$3:$L$30) -> 694 | N9: بركر 13 بوليش | O9: =M9-sells[[#This Row],[Transfer]] -> 118
A10: بركر 14 بطاطا | B10: 1056 | C10: =SUMIF(productionSection[Product Name],'كشف الانتاج'!C15,productionSection[Amount]) -> 360 | E10: فلر 26 عادي | F10: 6128 | G10: ='كشف الانتاج'!C15 -> بركر 13 عادي | H10: =SUMIF(sells[Product Name],sells[[#This Row],[Main Name]],sells[Amount]) -> 240 | K10: فلر 26 عادي | L10: 6872 | M10: =SUMIF($K$3:$K$30,sells[[#This Row],[Main Name]],$L$3:$L$30) -> 256 | N10: بركر 13 عادي | O10: =M10-sells[[#This Row],[Transfer]] -> 16
A11: بركر 14 بطاطا | B11: 624 | C11: =SUMIF(productionSection[Product Name],'كشف الانتاج'!C16,productionSection[Amount]) -> 624 | E11: فلر 26 بوليش | F11: 3044 | G11: ='كشف الانتاج'!C16 -> بركر 10 عادي | H11: =SUMIF(sells[Product Name],sells[[#This Row],[Main Name]],sells[Amount]) -> 970 | K11: فلر 26 بوليش | L11: 2468 | M11: =SUMIF($K$3:$K$30,sells[[#This Row],[Main Name]],$L$3:$L$30) -> 836 | N11: بركر 10 عادي | O11: =M11-sells[[#This Row],[Transfer]] -> -134
A12: دبل باسطون | B12: 3240 | C12: =SUMIF(productionSection[Product Name],'كشف الانتاج'!C17,productionSection[Amount]) -> 0 | E12: سابوي | F12: 1525 | G12: ='كشف الانتاج'!C17 -> بركر 10 بطاطا | H12: =SUMIF(sells[Product Name],sells[[#This Row],[Main Name]],sells[Amount]) -> 0 | K12: سابوي | L12: 1605 | M12: =SUMIF($K$3:$K$30,sells[[#This Row],[Main Name]],$L$3:$L$30) -> 0 | N12: بركر 10 بطاطا | O12: =M12-sells[[#This Row],[Transfer]] -> 0
A13: بركر 13 بطاطا | B13: 104 | C13: =SUMIF(productionSection[Product Name],'كشف الانتاج'!C18,productionSection[Amount]) -> 240 | E13: فلر 26 سميد | F13: 1416 | G13: ='كشف الانتاج'!C18 -> مثلث | H13: =SUMIF(sells[Product Name],sells[[#This Row],[Main Name]],sells[Amount]) -> 270 | K13: فلر 26 سميد | L13: 272 | M13: =SUMIF($K$3:$K$30,sells[[#This Row],[Main Name]],$L$3:$L$30) -> 138 | N13: مثلث | O13: =M13-sells[[#This Row],[Transfer]] -> -132
A14: بركر 13 بطاطا | B14: 958 | C14: =SUMIF(productionSection[Product Name],'كشف الانتاج'!C19,productionSection[Amount]) -> 6139 | E14: دبل باسطون | F14: 2885 | G14: ='كشف الانتاج'!C19 -> فلر 26 عادي | H14: =SUMIF(sells[Product Name],sells[[#This Row],[Main Name]],sells[Amount]) -> 6128 | K14: دبل باسطون | L14: 2550 | M14: =SUMIF($K$3:$K$30,sells[[#This Row],[Main Name]],$L$3:$L$30) -> 6872 | N14: فلر 26 عادي | O14: =M14-sells[[#This Row],[Transfer]] -> 744
A15: سابوي | B15: 2920 | C15: =SUMIF(productionSection[Product Name],'كشف الانتاج'!C20,productionSection[Amount]) -> 3276 | E15: بركر 11 | F15: 516 | G15: ='كشف الانتاج'!C20 -> فلر 26 بوليش | H15: =SUMIF(sells[Product Name],sells[[#This Row],[Main Name]],sells[Amount]) -> 3044 | K15: بركر 11 | L15: 784 | M15: =SUMIF($K$3:$K$30,sells[[#This Row],[Main Name]],$L$3:$L$30) -> 2468 | N15: فلر 26 بوليش | O15: =M15-sells[[#This Row],[Transfer]] -> -576
A16: بركر 13 بوليش | B16: 0 | C16: =SUMIF(productionSection[Product Name],'كشف الانتاج'!C21,productionSection[Amount]) -> 1456 | E16: همام مشرح | F16: 50 | G16: ='كشف الانتاج'!C21 -> فلر 26 سميد | H16: =SUMIF(sells[Product Name],sells[[#This Row],[Main Name]],sells[Amount]) -> 1416 | K16: همام مشرح | L16: 15 | M16: =SUMIF($K$3:$K$30,sells[[#This Row],[Main Name]],$L$3:$L$30) -> 272 | N16: فلر 26 سميد | O16: =M16-sells[[#This Row],[Transfer]] -> -1144
A17: بركر 13 بوليش | B17: 860 | C17: =SUMIF(productionSection[Product Name],'كشف الانتاج'!C22,productionSection[Amount]) -> 3240 | E17: همام عادي | F17: 222 | G17: ='كشف الانتاج'!C22 -> دبل باسطون | H17: =SUMIF(sells[Product Name],sells[[#This Row],[Main Name]],sells[Amount]) -> 2885 | K17: همام عادي | L17: 210 | M17: =SUMIF($K$3:$K$30,sells[[#This Row],[Main Name]],$L$3:$L$30) -> 2550 | N17: دبل باسطون | O17: =M17-sells[[#This Row],[Transfer]] -> -335
... A20: بركر 13 عادي | B20: 360 | C20: =SUMIF(productionSection[Product Name],'كشف الانتاج'!C25,productionSection[Amount]) -> 224 | E20: عيش ابيض | F20: 239 | G20: ='كشف الانتاج'!C25 -> همام عادي | H20: =SUMIF(sells[Product Name],sells[[#This Row],[Main Name]],sells[Amount]) -> 222 | K20: مثلث | L20: 138 | M20: =SUMIF($K$3:$K$30,sells[[#This Row],[Main Name]],$L$3:$L$30) -> 210 | N20: همام مشرح | O20: =M20-sells[[#This Row],[Transfer]] -> -12
A21: همام عادي | B21: 224 | C21: =SUMIF(productionSection[Product Name],'كشف الانتاج'!C26,productionSection[Amount]) -> 45 | E21: بركر 10 عادي | F21: 970 | G21: ='كشف الانتاج'!C26 -> همام مشرح | H21: =summation_func(names[humam],sells[Product Name],sells[Amount]) -> #NAME? | K21: عيش ابيض | L21: 409 | M21: =SUMIF($K$3:$K$30,sells[[#This Row],[Main Name]],$L$3:$L$30) -> 15 | N21: بيبي | O21: =M21-sells[[#This Row],[Transfer]] -> #NAME?
A22: بركر 10 عادي | B22: 0 | C22: =SUMIF(productionSection[Product Name],'كشف الانتاج'!C27,productionSection[Amount]) -> 0 | E22: اجرة النقل | F22: 92 | G22: ='كشف الانتاج'!C27 -> وسط باسطون | H22: =SUMIF(sells[Product Name],sells[[#This Row],[Main Name]],sells[Amount]) -> 0 | K22: وسط باسطون | L22: 30 | M22: =SUMIF($K$3:$K$30,sells[[#This Row],[Main Name]],$L$3:$L$30) -> 30 | N22: توست عادي | O22: =M22-sells[[#This Row],[Transfer]] -> 30
A23: بركر 10 عادي | B23: 624 | C23: =SUMIF(productionSection[Product Name],'كشف الانتاج'!C28,productionSection[Amount]) -> 0 | E23: كراتين صغير | F23: 99 | G23: ='كشف الانتاج'!C28 -> توست عادي | H23: =SUMIF(sells[Product Name],sells[[#This Row],[Main Name]],sells[Amount]) -> 0 | K23: بركر 10 عادي | L23: 836 | M23: =SUMIF($K$3:$K$30,sells[[#This Row],[Main Name]],$L$3:$L$30) -> 20 | N23: توست بطاطا | O23: =M23-sells[[#This Row],[Transfer]] -> 20
A24: همام مشرح | B24: 45 | C24: =SUMIF(productionSection[Product Name],'كشف الانتاج'!C29,productionSection[Amount]) -> 0 | E24: سلة كبير | F24: 436 | G24: ='كشف الانتاج'!C29 -> توست بطاطا | H24: =SUMIF(sells[Product Name],sells[[#This Row],[Main Name]],sells[Amount]) -> 0 | K24: همام كرنشي | L24: 100 | M24: =SUMIF($K$3:$K$30,sells[[#This Row],[Main Name]],$L$3:$L$30) -> 0 | N24: عيش ابيض | O24: =M24-sells[[#This Row],[Transfer]] -> 0
A25: مثلث | B25: 0 | C25: =SUMIF(productionSection[Product Name],'كشف الانتاج'!C30,productionSection[Amount]) -> 0 | E25: سلة صغير | F25: 3179 | G25: ='كشف الانتاج'!C30 -> عيش ابيض | H25: =SUMIF(sells[Product Name],sells[[#This Row],[Main Name]],sells[Amount]) -> 239 | K25: اجره | L25: 147 | M25: =SUMIF($K$3:$K$30,sells[[#This Row],[Main Name]],$L$3:$L$30) -> 409 | N25: عيش اسمر | O25: =M25-sells[[#This Row],[Transfer]] -> 170
A26: مثلث | B26: 240 | C26: =SUMIF(productionSection[Product Name],'كشف الانتاج'!C31,productionSection[Amount]) -> 0 | E26: سابوي بوليش | F26: 1614 | G26: ='كشف الانتاج'!C31 -> عيش اسمر | H26: =SUMIF(sells[Product Name],sells[[#This Row],[Main Name]],sells[Amount]) -> 20 | K26: بركر 13 شعير | L26: 60 | M26: =SUMIF($K$3:$K$30,sells[[#This Row],[Main Name]],$L$3:$L$30) -> 56 | N26: بركر 11 | O26: =M26-sells[[#This Row],[Transfer]] -> 36
A27: بركر 11 | B27: 0 | C27: =SUMIF(productionSection[Product Name],'كشف الانتاج'!C32,productionSection[Amount]) -> 388 | E27: الاجمالي | F27: 86507 | G27: ='كشف الانتاج'!C32 -> بركر 11 | H27: =summation_func(names[burger 11],sells[Product Name],sells[Amount]) -> #NAME? | K27: سلة كبير | L27: 342 | M27: =SUMIF($K$3:$K$30,sells[[#This Row],[Main Name]],$L$3:$L$30) -> 784 | N27: باكيت | O27: =M27-sells[[#This Row],[Transfer]] -> #NAME?
A28: وسط باكيت | B28: 0 | C28: =SUMIF(productionSection[Product Name],'كشف الانتاج'!C33,productionSection[Amount]) -> 0 | G28: ='كشف الانتاج'!C33 -> باكيت | H28: =SUMIF(sells[Product Name],sells[[#This Row],[Main Name]],sells[Amount]) -> 0 | K28: سلة صغير | L28: 2577 | M28: =SUMIF($K$3:$K$30,sells[[#This Row],[Main Name]],$L$3:$L$30) -> 0 | N28: وسط باكيت | O28: =M28-sells[[#This Row],[Transfer]] -> 0
A29: وسط باكيت | B29: 0 | C29: =SUMIF(productionSection[Product Name],'كشف الانتاج'!C34,productionSection[Amount]) -> 0 | G29: ='كشف الانتاج'!C34 -> وسط باكيت | H29: =SUMIF(sells[Product Name],sells[[#This Row],[Main Name]],sells[Amount]) -> 0 | K29: وسط باكيت | L29: 140 | M29: =SUMIF($K$3:$K$30,sells[[#This Row],[Main Name]],$L$3:$L$30) -> 140 | N29: بركر 13 شعير | O29: =M29-sells[[#This Row],[Transfer]] -> 140
A30: بركر 14 عادي | B30: 0 | C30: =SUMIF(productionSection[Product Name],'كشف الانتاج'!C35,productionSection[Amount]) -> 0 | G30: ='كشف الانتاج'!C35 -> بركر 13 شعير | H30: =SUMIF(sells[Product Name],sells[[#This Row],[Main Name]],sells[Amount]) -> 0 | K30: كنتاكي اسمر | L30: 400 | M30: =SUMIF($K$3:$K$30,sells[[#This Row],[Main Name]],$L$3:$L$30) -> 60 | N30: توست اسمر | O30: =M30-sells[[#This Row],[Transfer]] -> 60
A31: بركر 11 | B31: 388 | C31: =SUMIF(productionSection[Product Name],'كشف الانتاج'!C36,productionSection[Amount]) -> 0 | G31: ='كشف الانتاج'!C36 -> توست اسمر | H31: =SUMIF(sells[Product Name],sells[[#This Row],[Main Name]],sells[Amount]) -> 0 | N31: فلر 26 اسمر | O31: =M31-sells[[#This Row],[Transfer]] -> 0
A32: بركر 11 | B32: 0 | C32: =SUMIF(productionSection[Product Name],'كشف الانتاج'!C37,productionSection[Amount]) -> 0 | G32: ='كشف الانتاج'!C37 -> فلر 26 اسمر | H32: =SUMIF(sells[Product Name],sells[[#This Row],[Main Name]],sells[Amount]) -> 0
A33: بركر 13 عادي | B33: 0 | C33: =SUMIF(productionSection[Product Name],'كشف الانتاج'!C38,productionSection[Amount]) -> 0 | G33: ='كشف الانتاج'!C38 -> 0 | H33: =SUMIF(sells[Product Name],sells[[#This Row],[Main Name]],sells[Amount]) -> 0
A34: فلر 26 عادي | B34: 0 | C34: =SUMIF(productionSection[Product Name],'كشف الانتاج'!#REF!,productionSection[Amount]) -> 0 | G34: ='كشف الانتاج'!#REF! -> #REF! | H34: =SUMIF(sells[Product Name],sells[[#This Row],[Main Name]],sells[Amount]) -> 0
A35: فلر 26 عادي | B35: 0 | C35: =SUMIF(productionSection[Product Name],'كشف الانتاج'!C40,productionSection[Amount]) -> 0 | G35: ='كشف الانتاج'!C40 -> 0 | H35: =SUMIF(sells[Product Name],sells[[#This Row],[Main Name]],sells[Amount]) -> 0
A36: بركر 14 بوليش | B36: 0 | C36: =SUMIF(productionSection[Product Name],'كشف الانتاج'!C41,productionSection[Amount]) -> 0 | G36: ='كشف الانتاج'!C41 -> 0 | H36: =SUMIF(sells[Product Name],sells[[#This Row],[Main Name]],sells[Amount]) -> 0
A37: بركر 13 شعير | B37: 0 | C37: =SUMIF(productionSection[Product Name],'كشف الانتاج'!C42,productionSection[Amount]) -> 0 | G37: ='كشف الانتاج'!C42 -> 0 | H37: =SUMIF(sells[Product Name],sells[[#This Row],[Main Name]],sells[Amount]) -> 0
A38: بركر 13 شعير | B38: 0 | C38: =SUMIF(productionSection[Product Name],'كشف الانتاج'!C43,productionSection[Amount]) -> 0 | G38: ='كشف الانتاج'!C43 -> 0 | H38: =SUMIF(sells[Product Name],sells[[#This Row],[Main Name]],sells[Amount]) -> 0
A39: كنتاكي | B39: 0 | C39: =SUMIF(productionSection[Product Name],'كشف الانتاج'!C44,productionSection[Amount]) -> 0 | G39: ='كشف الانتاج'!C44 -> 0 | H39: =SUMIF(sells[Product Name],sells[[#This Row],[Main Name]],sells[Amount]) -> 0
A40: كنتاكي | B40: 7056 | C40: =SUMIF(productionSection[Product Name],'كشف الانتاج'!C45,productionSection[Amount]) -> 0 | G40: ='كشف الانتاج'!C45 -> 0 | H40: =SUMIF(sells[Product Name],sells[[#This Row],[Main Name]],sells[Amount]) -> 0
A41: كنتاكي | B41: 33648 | C41: =SUMIF(productionSection[Product Name],'كشف الانتاج'!C46,productionSection[Amount]) -> 0 | G41: ='كشف الانتاج'!C47 -> 0 | H41: =SUMIF(sells[Product Name],sells[[#This Row],[Main Name]],sells[Amount]) -> 0
C42: =SUMIF(productionSection[Product Name],'كشف الانتاج'!C47,productionSection[Amount]) -> 0
...

Sheet عداد الخلفات
A1: ت | B1: فلر 26 عادي | C1: فلر 26 بوليش | D1: فلر 26 سميد | E1: دبل باسطون | F1: سابوي | G1: سابوي بوليش | H1: همام عادي | I1: همام مشرح | J1: بركر 11 | K1: بركر 14 عادي | L1: بركر 13 عادي | M1: بركر 14 بوليش | N1: كنتاكي | O1: العمل
A2: 1 | B2: 210 | C2: 364
A3: 2 | B3: 574
A4: 3 | F4: 630
A5: 4 | B5: 238 | C5: 364
A6: 5 | B6: 238 | C6: 364
A7: 6 | F7: 650
A8: 7 | B8: 224 | D8: 364
A9: 8 | B9: 224 | C9: 364
A10: 9 | B10: 602
A11: 10 | E11: 580
A12: 11 | B12: 224 | D12: 364
A13: 12 | E13: 580
A14: 13 | E14: 580
A15: 14 | B15: 252 | C15: 364
A16: 15 | B16: 238 | C16: 364
A17: 16 | F17: 630
A18: 17 | B18: 252 | D18: 364
A19: 18 | B19: 588
A20: 19 | B20: 210 | C20: 364
A21: 20 | B21: 224 | C21: 364
A22: 21 | B22: 602
A23: 22 | B23: 588
A24: 23 | E24: 580
A25: 24 | B25: 84 | D25: 364 | H25: 224 | I25: 45
A26: 25 | F26: 630
A27: 26 | E27: 200 | F27: 380
A28: 27 | B28: 21 | C28: 364
A29: 28 | B29: 182 | E29: 380
A30: 29 | B30: 364 | E30: 340
A31: 30
A32: 31
A33: 32
A34: 33
A35: 34
A36: 35
A37: المجموع | B37: =SUBTOTAL(109,B2:B36) -> 6139 | C37: =SUBTOTAL(109,C2:C36) -> 3276 | D37: =SUBTOTAL(109,D2:D36) -> 1456 | E37: =SUBTOTAL(109,E2:E36) -> 3240 | F37: =SUBTOTAL(109,F2:F36) -> 2920 | G37: =SUBTOTAL(109,G2:G36) -> 0 | H37: =SUBTOTAL(109,H2:H36) -> 224 | I37: =SUBTOTAL(109,I2:I36) -> 45 | ... N37: =SUBTOTAL(109,N2:N36) -> 0 | O37: 29
A38: ت | B38: بركر 14 عادي | C38: بركر 14 بوليش | D38: بركر 14 بطاطا | E38: بركر 13 بطاطا | F38: بركر 13 بوليش | G38: بركر 13 عادي | H38: بركر 10 عادي | I38: مثلث | J38: وسط باكيت | K38: بركر 11 | L38: فلر 26 عادي | M38: بركر 13 شعير | N38: كنتاكي | O38: العمل
A39: 1 | D39: 612
A40: 2 | D40: 444 | E40: 260
...

Sheet عداد النازل
A1: ت | B1: ر.المادة | C1: اسم المادة | D1: عداد النازل من المصعد | U1: مجموع | V1: مناقلات | W1: فرق
A2: 1 | B2: ='كشف الانتاج'!B8 -> 1 | C2: =IF(B2<>"",VLOOKUP(B2,sammary[[رمز المادة]:[اسم المادة]],2,FALSE),"") -> كنتاكي | D2: 400 | E2: 400 | F2: 19780 | G2: 5650 | H2: 4300 | I2: 1263 | J2: 6723 | U2: =SUM(D2:T2)+V2 -> #NAME? | V2: =Transfer(B2,transferTable[ر.م.مستورد],transferTable[ر.م.مصدر],transferTable[الكمية]) -> #NAME? | W2: ='كشف الانتاج'!M8 -> #NAME?
A3: 2 | B3: ='كشف الانتاج'!B9 -> 12 | C3: =IF(B3<>"",VLOOKUP(B3,sammary[[رمز المادة]:[اسم المادة]],2,FALSE),"") -> كنتاكي اسمر | U3: =SUM(D3:T3)+V3 -> #NAME? | V3: =Transfer(B3,transferTable[ر.م.مستورد],transferTable[ر.م.مصدر],transferTable[الكمية]) -> #NAME? | W3: ='كشف الانتاج'!M9 -> #NAME?
A4: 3 | B4: ='كشف الانتاج'!B10 -> 141 | C4: =IF(B4<>"",VLOOKUP(B4,sammary[[رمز المادة]:[اسم المادة]],2,FALSE),"") -> بركر 14 عادي | D4: 1400 | E4: 600 | F4: 200 | G4: 800 | H4: 340 | I4: 1000 | J4: 128 | K4: 1600 | L4: 470 | U4: =SUM(D4:T4)+V4 -> #NAME? | V4: =Transfer(B4,transferTable[ر.م.مستورد],transferTable[ر.م.مصدر],transferTable[الكمية]) -> #NAME? | W4: ='كشف الانتاج'!M10 -> #NAME?
A5: 4 | B5: ='كشف الانتاج'!B11 -> 142 | C5: =IF(B5<>"",VLOOKUP(B5,sammary[[رمز المادة]:[اسم المادة]],2,FALSE),"") -> بركر 14 بوليش | D5: 200 | E5: 1600 | F5: 400 | G5: 200 | H5: 170 | I5: 340 | J5: 400 | K5: 510 | L5: 110 | M5: 400 | N5: 612 | O5: 218 | U5: =SUM(D5:T5)+V5 -> #NAME? | V5: =Transfer(B5,transferTable[ر.م.مستورد],transferTable[ر.م.مصدر],transferTable[الكمية]) -> #NAME? | W5: ='كشف الانتاج'!M11 -> #NAME?
A6: 5 | B6: ='كشف الانتاج'!B12 -> 143 | C6: =IF(B6<>"",VLOOKUP(B6,sammary[[رمز المادة]:[اسم المادة]],2,FALSE),"") -> بركر 14 بطاطا | D6: 400 | E6: 200 | F6: 140 | G6: 850 | H6: 16 | U6: =SUM(D6:T6)+V6 -> #NAME? | V6: =Transfer(B6,transferTable[ر.م.مستورد],transferTable[ر.م.مصدر],transferTable[الكمية]) -> #NAME? | W6: ='كشف الانتاج'!M12 -> #NAME?
A7: 6 | B7: ='كشف الانتاج'!B13 -> 133 | C7: =IF(B7<>"",VLOOKUP(B7,sammary[[رمز المادة]:[اسم المادة]],2,FALSE),"") -> بركر 13 بطاطا | D7: 240 | E7: 240 | F7: 156 | G7: 186 | H7: 257 | U7: =SUM(D7:T7)+V7 -> #NAME? | V7: =Transfer(B7,transferTable[ر.م.مستورد],transferTable[ر.م.مصدر],transferTable[الكمية]) -> #NAME? | W7: ='كشف الانتاج'!M13 -> #NAME?
A8: 7 | B8: ='كشف الانتاج'!B14 -> 132 | C8: =IF(B8<>"",VLOOKUP(B8,sammary[[رمز المادة]:[اسم المادة]],2,FALSE),"") -> بركر 13 بوليش | D8: 240 | E8: 240 | F8: 240 | U8: =SUM(D8:T8)+V8 -> #NAME? | V8: =Transfer(B8,transferTable[ر.م.مستورد],transferTable[ر.م.مصدر],transferTable[الكمية]) -> #NAME? | W8: ='كشف الانتاج'!M14 -> #NAME?
A9: 8 | B9: ='كشف الانتاج'!B15 -> 131 | C9: بركر 13 عادي | D9: 264 | U9: =SUM(D9:T9)+V9 -> #NAME? | V9: =Transfer(B9,transferTable[ر.م.مستورد],transferTable[ر.م.مصدر],transferTable[الكمية]) -> #NAME? | W9: ='كشف الانتاج'!M15 -> #NAME?
A10: 9 | B10: ='كشف الانتاج'!B16 -> 101 | C10: =IF(B10<>"",VLOOKUP(B10,sammary[[رمز المادة]:[اسم المادة]],2,FALSE),"") -> بركر 10 عادي | D10: 468 | E10: 150 | U10: =SUM(D10:T10)+V10 -> #NAME? | V10: =Transfer(B10,transferTable[ر.م.مستورد],transferTable[ر.م.مصدر],transferTable[الكمية]) -> #NAME? | W10: ='كشف الانتاج'!M16 -> #NAME?
A11: 10 | B11: ='كشف الانتاج'!B17 -> 102 | C11: =IF(B11<>"",VLOOKUP(B11,sammary[[رمز المادة]:[اسم المادة]],2,FALSE),"") -> بركر 10 بطاطا | U11: =SUM(D11:T11)+V11 -> #NAME? | V11: =Transfer(B11,transferTable[ر.م.مستورد],transferTable[ر.م.مصدر],transferTable[الكمية]) -> #NAME? | W11: ='كشف الانتاج'!M17 -> #NAME?
A12: 11 | B12: ='كشف الانتاج'!B18 -> 666 | C12: =IF(B12<>"",VLOOKUP(B12,sammary[[رمز المادة]:[اسم المادة]],2,FALSE),"") -> مثلث | D12: 239 | U12: =SUM(D12:T12)+V12 -> #NAME? | V12: =Transfer(B12,transferTable[ر.م.مستورد],transferTable[ر.م.مصدر],transferTable[الكمية]) -> #NAME? | W12: ='كشف الانتاج'!M18 -> #NAME?
A13: 12 | B13: ='كشف الانتاج'!B19 -> 261 | C13: =IF(B13<>"",VLOOKUP(B13,sammary[[رمز المادة]:[اسم المادة]],2,FALSE),"") -> فلر 26 عادي | D13: 400 | E13: 1100 | F13: 600 | G13: 600 | H13: 760 | I13: 180 | J13: 100 | K13: 170 | L13: 800 | M13: 200 | N13: 380 | O13: 266 | P13: 160 | Q13: 354 | U13: =SUM(D13:T13)+V13 -> #NAME? | V13: =Transfer(B13,transferTable[ر.م.مستورد],transferTable[ر.م.مصدر],transferTable[الكمية]) -> #NAME? | W13: ='كشف الانتاج'!M19 -> #NAME?
A14: 13 | B14: ='كشف الانتاج'!B20 -> 262 | C14: =IF(B14<>"",VLOOKUP(B14,sammary[[رمز المادة]:[اسم المادة]],2,FALSE),"") -> فلر 26 بوليش | D14: 900 | E14: 1000 | F14: 160 | G14: 230 | H14: 150 | I14: 96 | J14: 600 | U14: =SUM(D14:T14)+V14 -> #NAME? | V14: =Transfer(B14,transferTable[ر.م.مستورد],transferTable[ر.م.مصدر],transferTable[الكمية]) -> #NAME? | W14: ='كشف الانتاج'!M20 -> #NAME?
A15: 14 | B15: ='كشف الانتاج'!B21 -> 263 | C15: =IF(B15<>"",VLOOKUP(B15,sammary[[رمز المادة]:[اسم المادة]],2,FALSE),"") -> فلر 26 سميد | D15: 1000 | E15: 300 | F15: 58 | G15: 38 | U15: =SUM(D15:T15)+V15 -> #NAME? | V15: =Transfer(B15,transferTable[ر.م.مستورد],transferTable[ر.م.مصدر],transferTable[الكمية]) -> #NAME? | W15: ='كشف الانتاج'!M21 -> #NAME?
A16: 15 | B16: ='كشف الانتاج'!B22 -> 32 | C16: =IF(B16<>"",VLOOKUP(B16,sammary[[رمز المادة]:[اسم المادة]],2,FALSE),"") -> دبل باسطون | D16: 800 | E16: 200 | F16: 600 | G16: 115 | H16: 400 | I16: 220 | J16: 400 | K16: 110 | U16: =SUM(D16:T16)+V16 -> #NAME? | V16: =Transfer(B16,transferTable[ر.م.مستورد],transferTable[ر.م.مصدر],transferTable[الكمية]) -> #NAME? | W16: ='كشف الانتاج'!M22 -> #NAME?
A17: 16 | B17: ='كشف الانتاج'!B23 -> 301 | C17: =IF(B17<>"",VLOOKUP(B17,sammary[[رمز المادة]:[اسم المادة]],2,FALSE),"") -> سابوي | D17: 600 | E17: 600 | F17: 110 | G17: 95 | U17: =SUM(D17:T17)+V17 -> #NAME? | V17: =Transfer(B17,transferTable[ر.م.مستورد],transferTable[ر.م.مصدر],transferTable[الكمية]) -> #NAME? | W17: ='كشف الانتاج'!M23 -> #NAME?
A18: 17 | B18: 302 | C18: سابوي بوليش | D18: 800 | E18: 200 | F18: 175 | G18: 300 | H18: 135 | U18: =SUM(D18:T18)+V18 -> #NAME? | V18: =Transfer(B18,transferTable[ر.م.مستورد],transferTable[ر.م.مصدر],transferTable[الكمية]) -> #NAME? | W18: ='كشف الانتاج'!M24 -> #NAME?
A19: 18 | B19: ='كشف الانتاج'!B25 -> 51 | C19: همام عادي | D19: 224 | U19: =SUM(D19:T19)+V19 -> #NAME? | V19: =Transfer(B19,transferTable[ر.م.مستورد],transferTable[ر.م.مصدر],transferTable[الكمية]) -> #NAME? | W19: ='كشف الانتاج'!M25 -> #NAME?
A20: 19 | B20: ='كشف الانتاج'!B26 -> 52 | C20: =IF(B20<>"",VLOOKUP(B20,sammary[[رمز المادة]:[اسم المادة]],2,FALSE),"") -> همام مشرح | D20: 45 | U20: =SUM(D20:T20)+V20 -> #NAME? | V20: =Transfer(B20,transferTable[ر.م.مستورد],transferTable[ر.م.مصدر],transferTable[الكمية]) -> #NAME? | W20: ='كشف الانتاج'!M26 -> #NAME?
A21: 20 | B21: ='كشف الانتاج'!B27 -> 53 | C21: =IF(B21<>"",VLOOKUP(B21,sammary[[رمز المادة]:[اسم المادة]],2,FALSE),"") -> وسط باسطون | U21: =SUM(D21:T21)+V21 -> #NAME? | V21: =Transfer(B21,transferTable[ر.م.مستورد],transferTable[ر.م.مصدر],transferTable[الكمية]) -> #NAME? | W21: ='كشف الانتاج'!M27 -> #NAME?
A22: 21 | B22: ='كشف الانتاج'!B28 -> 41 | C22: =IF(B22<>"",VLOOKUP(B22,sammary[[رمز المادة]:[اسم المادة]],2,FALSE),"") -> توست عادي | U22: =SUM(D22:T22)+V22 -> #NAME? | V22: =Transfer(B22,transferTable[ر.م.مستورد],transferTable[ر.م.مصدر],transferTable[الكمية]) -> #NAME? | W22: ='كشف الانتاج'!M28 -> #NAME?
A23: 22 | B23: ='كشف الانتاج'!B29 -> 42 | C23: =IF(B23<>"",VLOOKUP(B23,sammary[[رمز المادة]:[اسم المادة]],2,FALSE),"") -> توست بطاطا | U23: =SUM(D23:T23)+V23 -> #NAME? | V23: =Transfer(B23,transferTable[ر.م.مستورد],transferTable[ر.م.مصدر],transferTable[الكمية]) -> #NAME? | W23: ='كشف الانتاج'!M29 -> #NAME?
A24: 23 | B24: ='كشف الانتاج'!B30 -> 81 | C24: =IF(B24<>"",VLOOKUP(B24,sammary[[رمز المادة]:[اسم المادة]],2,FALSE),"") -> عيش ابيض | U24: =SUM(D24:T24)+V24 -> #NAME? | V24: =Transfer(B24,transferTable[ر.م.مستورد],transferTable[ر.م.مصدر],transferTable[الكمية]) -> #NAME? | W24: ='كشف الانتاج'!M30 -> #NAME?
A25: 24 | B25: ='كشف الانتاج'!B31 -> 82 | C25: =IF(B25<>"",VLOOKUP(B25,sammary[[رمز المادة]:[اسم المادة]],2,FALSE),"") -> عيش اسمر | U25: =SUM(D25:T25)+V25 -> #NAME? | V25: =Transfer(B25,transferTable[ر.م.مستورد],transferTable[ر.م.مصدر],transferTable[الكمية]) -> #NAME? | W25: ='كشف الانتاج'!M31 -> #NAME?
A26: 25 | B26: ='كشف الانتاج'!B32 -> 11 | C26: =IF(B26<>"",VLOOKUP(B26,sammary[[رمز المادة]:[اسم المادة]],2,FALSE),"") -> بركر 11 | D26: 36 | E26: 48 | F26: 534 | U26: =SUM(D26:T26)+V26 -> #NAME? | V26: =Transfer(B26,transferTable[ر.م.مستورد],transferTable[ر.م.مصدر],transferTable[الكمية]) -> #NAME? | W26: ='كشف الانتاج'!M32 -> #NAME?
A27: 26 | B27: ='كشف الانتاج'!B33 -> 9 | C27: =IF(B27<>"",VLOOKUP(B27,sammary[[رمز المادة]:[اسم المادة]],2,FALSE),"") -> باكيت | U27: =SUM(D27:T27)+V27 -> #NAME? | V27: =Transfer(B27,transferTable[ر.م.مستورد],transferTable[ر.م.مصدر],transferTable[الكمية]) -> #NAME? | W27: ='كشف الانتاج'!M33 -> #NAME?
A28: 27 | B28: ='كشف الانتاج'!B34 -> 92 | C28: =IF(B28<>"",VLOOKUP(B28,sammary[[رمز المادة]:[اسم المادة]],2,FALSE),"") -> وسط باكيت | U28: =SUM(D28:T28)+V28 -> #NAME? | V28: =Transfer(B28,transferTable[ر.م.مستورد],transferTable[ر.م.مصدر],transferTable[الكمية]) -> #NAME? | W28: ='كشف الانتاج'!M34 -> #NAME?
A29: 28 | B29: ='كشف الانتاج'!B35 -> 139 | C29: =IF(B29<>"",VLOOKUP(B29,sammary[[رمز المادة]:[اسم المادة]],2,FALSE),"") -> بركر 13 شعير | U29: =SUM(D29:T29)+V29 -> #NAME? | V29: =Transfer(B29,transferTable[ر.م.مستورد],transferTable[ر.م.مصدر],transferTable[الكمية]) -> #NAME? | W29: ='كشف الانتاج'!M35 -> #NAME?
A30: 29 | B30: ='كشف الانتاج'!B36 -> 49 | C30: =IF(B30<>"",VLOOKUP(B30,sammary[[رمز المادة]:[اسم المادة]],2,FALSE),"") -> توست اسمر | U30: =SUM(D30:T30)+V30 -> #NAME? | V30: =Transfer(B30,transferTable[ر.م.مستورد],transferTable[ر.م.مصدر],transferTable[الكمية]) -> #NAME? | W30: ='كشف الانتاج'!M36 -> #NAME?
A31: 30 | B31: ='كشف الانتاج'!B37 -> 269 | C31: =IF(B31<>"",VLOOKUP(B31,sammary[[رمز المادة]:[اسم المادة]],2,FALSE),"") -> فلر 26 اسمر | U31: =SUM(D31:T31)+V31 -> #NAME? | V31: =Transfer(B31,transferTable[ر.م.مستورد],transferTable[ر.م.مصدر],transferTable[الكمية]) -> #NAME? | W31: ='كشف الانتاج'!M37 -> #NAME?

Sheet متابعة تعبئة
A1: ت | B1: ر. المادة | C1: اسم المادة | D1: عدد الصواني | E1: عدد النقص
B2: 1 | C2: =IF(ele[[#This Row],[ر. المادة]]<> "",VLOOKUP(ele[[#This Row],[ر. المادة]],sammary[[رمز المادة]:[اسم المادة]],2,FALSE),"") -> كنتاكي | D2: 26 | E2: 10
B3: 1 | C3: =IF(ele[[#This Row],[ر. المادة]]<> "",VLOOKUP(ele[[#This Row],[ر. المادة]],sammary[[رمز المادة]:[اسم المادة]],2,FALSE),"") -> كنتاكي | D3: 22 | E3: 13
B4: 1 | C4: =IF(ele[[#This Row],[ر. المادة]]<> "",VLOOKUP(ele[[#This Row],[ر. المادة]],sammary[[رمز المادة]:[اسم المادة]],2,FALSE),"") -> كنتاكي | D4: 25 | E4: 50
B5: 1 | C5: =IF(ele[[#This Row],[ر. المادة]]<> "",VLOOKUP(ele[[#This Row],[ر. المادة]],sammary[[رمز المادة]:[اسم المادة]],2,FALSE),"") -> كنتاكي | D5: 26 | E5: 62
B6: 1 | C6: =IF(ele[[#This Row],[ر. المادة]]<> "",VLOOKUP(ele[[#This Row],[ر. المادة]],sammary[[رمز المادة]:[اسم المادة]],2,FALSE),"") -> كنتاكي | D6: 23 | E6: 56
B7: 1 | C7: =IF(ele[[#This Row],[ر. المادة]]<> "",VLOOKUP(ele[[#This Row],[ر. المادة]],sammary[[رمز المادة]:[اسم المادة]],2,FALSE),"") -> كنتاكي | D7: 23 | E7: 30
B8: 1 | C8: =IF(ele[[#This Row],[ر. المادة]]<> "",VLOOKUP(ele[[#This Row],[ر. المادة]],sammary[[رمز المادة]:[اسم المادة]],2,FALSE),"") -> كنتاكي | D8: 26 | E8: 28
B9: 1 | C9: =IF(ele[[#This Row],[ر. المادة]]<> "",VLOOKUP(ele[[#This Row],[ر. المادة]],sammary[[رمز المادة]:[اسم المادة]],2,FALSE),"") -> كنتاكي | D9: 20 | E9: 19
B10: 1 | C10: =IF(ele[[#This Row],[ر. المادة]]<> "",VLOOKUP(ele[[#This Row],[ر. المادة]],sammary[[رمز المادة]:[اسم المادة]],2,FALSE),"") -> كنتاكي | D10: 30 | E10: 53
B11: 1 | C11: =IF(ele[[#This Row],[ر. المادة]]<> "",VLOOKUP(ele[[#This Row],[ر. المادة]],sammary[[رمز المادة]:[اسم المادة]],2,FALSE),"") -> كنتاكي | D11: 26 | E11: 40
B12: 1 | C12: =IF(ele[[#This Row],[ر. المادة]]<> "",VLOOKUP(ele[[#This Row],[ر. المادة]],sammary[[رمز المادة]:[اسم المادة]],2,FALSE),"") -> كنتاكي | D12: 26 | E12: 36
B13: 1 | C13: =IF(ele[[#This Row],[ر. المادة]]<> "",VLOOKUP(ele[[#This Row],[ر. المادة]],sammary[[رمز المادة]:[اسم المادة]],2,FALSE),"") -> كنتاكي | D13: 26 | E13: 51
... B35: 1 | C35: =IF(ele[[#This Row],[ر. المادة]]<> "",VLOOKUP(ele[[#This Row],[ر. المادة]],sammary[[رمز المادة]:[اسم المادة]],2,FALSE),"") -> كنتاكي | D35: 21 | E35: 30
B36: 141 | C36: =IF(ele[[#This Row],[ر. المادة]]<> "",VLOOKUP(ele[[#This Row],[ر. المادة]],sammary[[رمز المادة]:[اسم المادة]],2,FALSE),"") -> بركر 14 عادي | D36: 26
B37: 141 | C37: =IF(ele[[#This Row],[ر. المادة]]<> "",VLOOKUP(ele[[#This Row],[ر. المادة]],sammary[[رمز المادة]:[اسم المادة]],2,FALSE),"") -> بركر 14 عادي | D37: 24
B38: 141 | C38: =IF(ele[[#This Row],[ر. المادة]]<> "",VLOOKUP(ele[[#This Row],[ر. المادة]],sammary[[رمز المادة]:[اسم المادة]],2,FALSE),"") -> بركر 14 عادي | D38: 26
B39: 141 | C39: =IF(ele[[#This Row],[ر. المادة]]<> "",VLOOKUP(ele[[#This Row],[ر. المادة]],sammary[[رمز المادة]:[اسم المادة]],2,FALSE),"") -> بركر 14 عادي | D39: 26
B40: 141 | C40: =IF(ele[[#This Row],[ر. المادة]]<> "",VLOOKUP(ele[[#This Row],[ر. المادة]],sammary[[رمز المادة]:[اسم المادة]],2,FALSE),"") -> بركر 14 عادي | D40: 25
B41: 141 | C41: =IF(ele[[#This Row],[ر. المادة]]<> "",VLOOKUP(ele[[#This Row],[ر. المادة]],sammary[[رمز المادة]:[اسم المادة]],2,FALSE),"") -> بركر 14 عادي | D41: 26 | E41: 2
B42: 141 | C42: =IF(ele[[#This Row],[ر. المادة]]<> "",VLOOKUP(ele[[#This Row],[ر. المادة]],sammary[[رمز المادة]:[اسم المادة]],2,FALSE),"") -> بركر 14 عادي | D42: 24
B43: 141 | C43: =IF(ele[[#This Row],[ر. المادة]]<> "",VLOOKUP(ele[[#This Row],[ر. المادة]],sammary[[رمز المادة]:[اسم المادة]],2,FALSE),"") -> بركر 14 عادي | D43: 26
B44: 141 | C44: =IF(ele[[#This Row],[ر. المادة]]<> "",VLOOKUP(ele[[#This Row],[ر. المادة]],sammary[[رمز المادة]:[اسم المادة]],2,FALSE),"") -> بركر 14 عادي | D44: 26
B45: 141 | C45: =IF(ele[[#This Row],[ر. المادة]]<> "",VLOOKUP(ele[[#This Row],[ر. المادة]],sammary[[رمز المادة]:[اسم المادة]],2,FALSE),"") -> بركر 14 عادي | D45: 24
B46: 141 | C46: =IF(ele[[#This Row],[ر. المادة]]<> "",VLOOKUP(ele[[#This Row],[ر. المادة]],sammary[[رمز المادة]:[اسم المادة]],2,FALSE),"") -> بركر 14 عادي | D46: 24
B47: 141 | C47: =IF(ele[[#This Row],[ر. المادة]]<> "",VLOOKUP(ele[[#This Row],[ر. المادة]],sammary[[رمز المادة]:[اسم المادة]],2,FALSE),"") -> بركر 14 عادي | D47: 26
B48: 141 | C48: =IF(ele[[#This Row],[ر. المادة]]<> "",VLOOKUP(ele[[#This Row],[ر. المادة]],sammary[[رمز المادة]:[اسم المادة]],2,FALSE),"") -> بركر 14 عادي | D48: 25
B49: 141 | C49: =IF(ele[[#This Row],[ر. المادة]]<> "",VLOOKUP(ele[[#This Row],[ر. المادة]],sammary[[رمز المادة]:[اسم المادة]],2,FALSE),"") -> بركر 14 عادي | D49: 26
B50: 141 | C50: =IF(ele[[#This Row],[ر. المادة]]<> "",VLOOKUP(ele[[#This Row],[ر. المادة]],sammary[[رمز المادة]:[اسم المادة]],2,FALSE),"") -> بركر 14 عادي | D50: 26
B51: 141 | C51: =IF(ele[[#This Row],[ر. المادة]]<> "",VLOOKUP(ele[[#This Row],[ر. المادة]],sammary[[رمز المادة]:[اسم المادة]],2,FALSE),"") -> بركر 14 عادي | D51: 24
B52: 141 | C52: =IF(ele[[#This Row],[ر. المادة]]<> "",VLOOKUP(ele[[#This Row],[ر. المادة]],sammary[[رمز المادة]:[اسم المادة]],2,FALSE),"") -> بركر 14 عادي | D52: 26
B53: 141 | C53: =IF(ele[[#This Row],[ر. المادة]]<> "",VLOOKUP(ele[[#This Row],[ر. المادة]],sammary[[رمز المادة]:[اسم المادة]],2,FALSE),"") -> بركر 14 عادي | D53: 26
... B58: 141 | C58: =IF(ele[[#This Row],[ر. المادة]]<> "",VLOOKUP(ele[[#This Row],[ر. المادة]],sammary[[رمز المادة]:[اسم المادة]],2,FALSE),"") -> بركر 14 عادي | D58: 25
B59: 142 | C59: =IF(ele[[#This Row],[ر. المادة]]<> "",VLOOKUP(ele[[#This Row],[ر. المادة]],sammary[[رمز المادة]:[اسم المادة]],2,FALSE),"") -> بركر 14 بوليش | D59: 26 | E59: 2
B60: 142 | C60: =IF(ele[[#This Row],[ر. المادة]]<> "",VLOOKUP(ele[[#This Row],[ر. المادة]],sammary[[رمز المادة]:[اسم المادة]],2,FALSE),"") -> بركر 14 بوليش | D60: 24 | E60: 1
B61: 142 | C61: =IF(ele[[#This Row],[ر. المادة]]<> "",VLOOKUP(ele[[#This Row],[ر. المادة]],sammary[[رمز المادة]:[اسم المادة]],2,FALSE),"") -> بركر 14 بوليش | D61: 26
B62: 142 | C62: =IF(ele[[#This Row],[ر. المادة]]<> "",VLOOKUP(ele[[#This Row],[ر. المادة]],sammary[[رمز المادة]:[اسم المادة]],2,FALSE),"") -> بركر 14 بوليش | D62: 26
B63: 142 | C63: =IF(ele[[#This Row],[ر. المادة]]<> "",VLOOKUP(ele[[#This Row],[ر. المادة]],sammary[[رمز المادة]:[اسم المادة]],2,FALSE),"") -> بركر 14 بوليش | D63: 25
B64: 142 | C64: =IF(ele[[#This Row],[ر. المادة]]<> "",VLOOKUP(ele[[#This Row],[ر. المادة]],sammary[[رمز المادة]:[اسم المادة]],2,FALSE),"") -> بركر 14 بوليش | D64: 26
B65: 142 | C65: =IF(ele[[#This Row],[ر. المادة]]<> "",VLOOKUP(ele[[#This Row],[ر. المادة]],sammary[[رمز المادة]:[اسم المادة]],2,FALSE),"") -> بركر 14 بوليش | D65: 26
...

Sheet كشف الانتاج
A1: اجمالي عمل شفت الكنتاكي | D1: ='عداد الخلفات'!O111 -> 35 | E1: شركة رغيف الكندى | W1: التاريخ | X1: 46169
A2: اجمالى عمل الدائرى | D2: ='عداد الخلفات'!O74 -> 11.5
A3: اجمالى عمل الاطوال | D3: ='عداد الخلفات'!O37 -> 29 | E3: كشف الانتاج | W3: الفرع | X3: الكرادة
A4: اجمالي عمل شفت الطوارئ | D4: 0
A5: اجمالى العمل الكلى | D5: =SUM(D1:D4) -> 75.5
A6: معلومات عن المادة | E6: خط الانتاج | N6: متبقي امس | P6: الوارد | R6: التلف | T6: المبيعات | V6: فرق الانتاج | X6: متبقي اليوم
A7: ت | B7: رمز المادة | C7: اسم المادة | D7: السعر | E7: شفت المسائي | F7: شفت الطوارئ | G7: المناقلات | H7: نقص الصواني بعد الخبز | I7: اكل عمال | J7: اجمالى الكمية | K7: قيمة الانتاج اليومى | L7: نازل | M7: الفرق عن النازل عند الخلفات | N7: كمية المتبقى امس | O7: قيمة المتبقى امس | P7: كمية الوارد فروع | Q7: قيمة الوارد فروع | R7: كمية التلف اليومى | S7: قيمة التلف اليومى | T7: كمية المبيعات اليومية | U7: قيمة المبيعات اليومية | V7: فرق الانتاج (المفقود) | W7: قيمة فرق الانتاج | X7: متبقي انتاج اليوم | Y7: قيمة متبقى انتاج اليوم
A8: 1 | B8: 1 | C8: كنتاكي | D8: 90 | E8: 40704 | F8: 9850 | G8: =Transfer(sammary[[#This Row],[رمز المادة]],transferTable[ر.م.مستورد],transferTable[ر.م.مصدر],transferTable[الكمية]) -> #NAME? | H8: 1133 | I8: 25 | J8: =SUM(sammary[[#This Row],[شفت المسائي]:[المناقلات]])-SUM(sammary[[#This Row],[نقص الصواني بعد الخبز]:[اكل عمال]])-sammary[[#This Row],[كمية التلف اليومى]] -> #NAME? | K8: =sammary[[#This Row],[اجمالى الكمية]]*sammary[[#This Row],[السعر]] -> #NAME? | L8: ='عداد النازل'!U2 -> #NAME? | M8: =sammary[[#This Row],[نازل]]-sammary[[#This Row],[اجمالى الكمية]] -> #NAME? | O8: =sammary[[#This Row],[كمية المتبقى امس]]*sammary[[#This Row],[السعر]] -> 0 | Q8: =sammary[[#This Row],[كمية الوارد فروع]]*sammary[[#This Row],[السعر]] -> 0 | S8: =sammary[[#This Row],[كمية التلف اليومى]]*sammary[[#This Row],[السعر]] -> 0 | T8: 47344 | U8: =sammary[[#This Row],[كمية المبيعات اليومية]]*sammary[[#This Row],[السعر]] -> 4260960 | V8: =(sammary[[#This Row],[اجمالى الكمية]]+sammary[[#This Row],[كمية المتبقى امس]]+sammary[[#This Row],[كمية الوارد فروع]])-(sammary[[#This Row],[كمية المبيعات اليومية]]+sammary[[#This Row],[متبقي انتاج اليوم]]) -> #NAME? | W8: =sammary[[#This Row],[فرق الانتاج (المفقود)]]*sammary[[#This Row],[السعر]] -> #NAME? | X8: 950 | Y8: =sammary[[#This Row],[متبقي انتاج اليوم]]*sammary[[#This Row],[السعر]] -> 85500
A9: 2 | B9: 12 | C9: كنتاكي اسمر | D9: 150 | E9: 0 | G9: =Transfer(sammary[[#This Row],[رمز المادة]],transferTable[ر.م.مستورد],transferTable[ر.م.مصدر],transferTable[الكمية]) -> #NAME? | H9: 0 | J9: =SUM(sammary[[#This Row],[شفت المسائي]:[المناقلات]])-SUM(sammary[[#This Row],[نقص الصواني بعد الخبز]:[اكل عمال]])-sammary[[#This Row],[كمية التلف اليومى]] -> #NAME? | K9: =sammary[[#This Row],[اجمالى الكمية]]*sammary[[#This Row],[السعر]] -> #NAME? | L9: ='عداد النازل'!U3 -> #NAME? | M9: =sammary[[#This Row],[نازل]]-sammary[[#This Row],[اجمالى الكمية]] -> #NAME? | O9: =sammary[[#This Row],[كمية المتبقى امس]]*sammary[[#This Row],[السعر]] -> 0 | Q9: =sammary[[#This Row],[كمية الوارد فروع]]*sammary[[#This Row],[السعر]] -> 0 | S9: =sammary[[#This Row],[كمية التلف اليومى]]*sammary[[#This Row],[السعر]] -> 0 | T9: 0 | U9: =sammary[[#This Row],[كمية المبيعات اليومية]]*sammary[[#This Row],[السعر]] -> 0 | V9: =(sammary[[#This Row],[اجمالى الكمية]]+sammary[[#This Row],[كمية المتبقى امس]]+sammary[[#This Row],[كمية الوارد فروع]])-(sammary[[#This Row],[كمية المبيعات اليومية]]+sammary[[#This Row],[متبقي انتاج اليوم]]) -> #NAME? | W9: =sammary[[#This Row],[فرق الانتاج (المفقود)]]*sammary[[#This Row],[السعر]] -> #NAME? | Y9: =sammary[[#This Row],[متبقي انتاج اليوم]]*sammary[[#This Row],[السعر]] -> 0
A10: 3 | B10: 141 | C10: بركر 14 عادي | D10: 300 | E10: 6943 | F10: 260 | G10: =Transfer(sammary[[#This Row],[رمز المادة]],transferTable[ر.م.مستورد],transferTable[ر.م.مصدر],transferTable[الكمية]) -> #NAME? | H10: 2 | I10: 48 | J10: =SUM(sammary[[#This Row],[شفت المسائي]:[المناقلات]])-SUM(sammary[[#This Row],[نقص الصواني بعد الخبز]:[اكل عمال]])-sammary[[#This Row],[كمية التلف اليومى]] -> #NAME? | K10: =sammary[[#This Row],[اجمالى الكمية]]*sammary[[#This Row],[السعر]] -> #NAME? | L10: ='عداد النازل'!U4 -> #NAME? | M10: =sammary[[#This Row],[نازل]]-sammary[[#This Row],[اجمالى الكمية]] -> #NAME? | O10: =sammary[[#This Row],[كمية المتبقى امس]]*sammary[[#This Row],[السعر]] -> 0 | Q10: =sammary[[#This Row],[كمية الوارد فروع]]*sammary[[#This Row],[السعر]] -> 0 | S10: =sammary[[#This Row],[كمية التلف اليومى]]*sammary[[#This Row],[السعر]] -> 0 | T10: 6806 | U10: =sammary[[#This Row],[كمية المبيعات اليومية]]*sammary[[#This Row],[السعر]] -> 2041800 | V10: =(sammary[[#This Row],[اجمالى الكمية]]+sammary[[#This Row],[كمية المتبقى امس]]+sammary[[#This Row],[كمية الوارد فروع]])-(sammary[[#This Row],[كمية المبيعات اليومية]]+sammary[[#This Row],[متبقي انتاج اليوم]]) -> #NAME? | W10: =sammary[[#This Row],[فرق الانتاج (المفقود)]]*sammary[[#This Row],[السعر]] -> #NAME? | X10: 231 | Y10: =sammary[[#This Row],[متبقي انتاج اليوم]]*sammary[[#This Row],[السعر]] -> 69300
A11: 4 | B11: 142 | C11: بركر 14 بوليش | D11: 400 | E11: 6308 | F11: 200 | G11: =Transfer(sammary[[#This Row],[رمز المادة]],transferTable[ر.م.مستورد],transferTable[ر.م.مصدر],transferTable[الكمية]) -> #NAME? | H11: 127 | J11: =SUM(sammary[[#This Row],[شفت المسائي]:[المناقلات]])-SUM(sammary[[#This Row],[نقص الصواني بعد الخبز]:[اكل عمال]])-sammary[[#This Row],[كمية التلف اليومى]] -> #NAME? | K11: =sammary[[#This Row],[اجمالى الكمية]]*sammary[[#This Row],[السعر]] -> #NAME? | L11: ='عداد النازل'!U5 -> #NAME? | M11: =sammary[[#This Row],[نازل]]-sammary[[#This Row],[اجمالى الكمية]] -> #NAME? | O11: =sammary[[#This Row],[كمية المتبقى امس]]*sammary[[#This Row],[السعر]] -> 0 | Q11: =sammary[[#This Row],[كمية الوارد فروع]]*sammary[[#This Row],[السعر]] -> 0 | S11: =sammary[[#This Row],[كمية التلف اليومى]]*sammary[[#This Row],[السعر]] -> 0 | T11: 6192 | U11: =sammary[[#This Row],[كمية المبيعات اليومية]]*sammary[[#This Row],[السعر]] -> 2476800 | V11: =(sammary[[#This Row],[اجمالى الكمية]]+sammary[[#This Row],[كمية المتبقى امس]]+sammary[[#This Row],[كمية الوارد فروع]])-(sammary[[#This Row],[كمية المبيعات اليومية]]+sammary[[#This Row],[متبقي انتاج اليوم]]) -> #NAME? | W11: =sammary[[#This Row],[فرق الانتاج (المفقود)]]*sammary[[#This Row],[السعر]] -> #NAME? | X11: 90 | Y11: =sammary[[#This Row],[متبقي انتاج اليوم]]*sammary[[#This Row],[السعر]] -> 36000
A12: 5 | B12: 143 | C12: بركر 14 بطاطا | D12: 450 | E12: 1680 | G12: =Transfer(sammary[[#This Row],[رمز المادة]],transferTable[ر.م.مستورد],transferTable[ر.م.مصدر],transferTable[الكمية]) -> #NAME? | H12: 62 | J12: =SUM(sammary[[#This Row],[شفت المسائي]:[المناقلات]])-SUM(sammary[[#This Row],[نقص الصواني بعد الخبز]:[اكل عمال]])-sammary[[#This Row],[كمية التلف اليومى]] -> #NAME? | K12: =sammary[[#This Row],[اجمالى الكمية]]*sammary[[#This Row],[السعر]] -> #NAME? | L12: ='عداد النازل'!U6 -> #NAME? | M12: =sammary[[#This Row],[نازل]]-sammary[[#This Row],[اجمالى الكمية]] -> #NAME? | O12: =sammary[[#This Row],[كمية المتبقى امس]]*sammary[[#This Row],[السعر]] -> 0 | Q12: =sammary[[#This Row],[كمية الوارد فروع]]*sammary[[#This Row],[السعر]] -> 0 | S12: =sammary[[#This Row],[كمية التلف اليومى]]*sammary[[#This Row],[السعر]] -> 0 | T12: 1570 | U12: =sammary[[#This Row],[كمية المبيعات اليومية]]*sammary[[#This Row],[السعر]] -> 706500 | V12: =(sammary[[#This Row],[اجمالى الكمية]]+sammary[[#This Row],[كمية المتبقى امس]]+sammary[[#This Row],[كمية الوارد فروع]])-(sammary[[#This Row],[كمية المبيعات اليومية]]+sammary[[#This Row],[متبقي انتاج اليوم]]) -> #NAME? | W12: =sammary[[#This Row],[فرق الانتاج (المفقود)]]*sammary[[#This Row],[السعر]] -> #NAME? | X12: 12 | Y12: =sammary[[#This Row],[متبقي انتاج اليوم]]*sammary[[#This Row],[السعر]] -> 5400
A13: 6 | B13: 133 | C13: بركر 13 بطاطا | D13: 450 | E13: 1062 | G13: =Transfer(sammary[[#This Row],[رمز المادة]],transferTable[ر.م.مستورد],transferTable[ر.م.مصدر],transferTable[الكمية]) -> #NAME? | H13: 0 | J13: =SUM(sammary[[#This Row],[شفت المسائي]:[المناقلات]])-SUM(sammary[[#This Row],[نقص الصواني بعد الخبز]:[اكل عمال]])-sammary[[#This Row],[كمية التلف اليومى]] -> #NAME? | K13: =sammary[[#This Row],[اجمالى الكمية]]*sammary[[#This Row],[السعر]] -> #NAME? | L13: ='عداد النازل'!U7 -> #NAME? | M13: =sammary[[#This Row],[نازل]]-sammary[[#This Row],[اجمالى الكمية]] -> #NAME? | O13: =sammary[[#This Row],[كمية المتبقى امس]]*sammary[[#This Row],[السعر]] -> 0 | Q13: =sammary[[#This Row],[كمية الوارد فروع]]*sammary[[#This Row],[السعر]] -> 0 | S13: =sammary[[#This Row],[كمية التلف اليومى]]*sammary[[#This Row],[السعر]] -> 0 | T13: 1074 | U13: =sammary[[#This Row],[كمية المبيعات اليومية]]*sammary[[#This Row],[السعر]] -> 483300 | V13: =(sammary[[#This Row],[اجمالى الكمية]]+sammary[[#This Row],[كمية المتبقى امس]]+sammary[[#This Row],[كمية الوارد فروع]])-(sammary[[#This Row],[كمية المبيعات اليومية]]+sammary[[#This Row],[متبقي انتاج اليوم]]) -> #NAME? | W13: =sammary[[#This Row],[فرق الانتاج (المفقود)]]*sammary[[#This Row],[السعر]] -> #NAME? | X13: 4 | Y13: =sammary[[#This Row],[متبقي انتاج اليوم]]*sammary[[#This Row],[السعر]] -> 1800
A14: 7 | B14: 132 | C14: بركر 13 بوليش | D14: 400 | E14: 860 | G14: =Transfer(sammary[[#This Row],[رمز المادة]],transferTable[ر.م.مستورد],transferTable[ر.م.مصدر],transferTable[الكمية]) -> #NAME? | H14: 110 | J14: =SUM(sammary[[#This Row],[شفت المسائي]:[المناقلات]])-SUM(sammary[[#This Row],[نقص الصواني بعد الخبز]:[اكل عمال]])-sammary[[#This Row],[كمية التلف اليومى]] -> #NAME? | K14: =sammary[[#This Row],[اجمالى الكمية]]*sammary[[#This Row],[السعر]] -> #NAME? | L14: ='عداد النازل'!U8 -> #NAME? | M14: =sammary[[#This Row],[نازل]]-sammary[[#This Row],[اجمالى الكمية]] -> #NAME? | O14: =sammary[[#This Row],[كمية المتبقى امس]]*sammary[[#This Row],[السعر]] -> 0 | Q14: =sammary[[#This Row],[كمية الوارد فروع]]*sammary[[#This Row],[السعر]] -> 0 | S14: =sammary[[#This Row],[كمية التلف اليومى]]*sammary[[#This Row],[السعر]] -> 0 | T14: 576 | U14: =sammary[[#This Row],[كمية المبيعات اليومية]]*sammary[[#This Row],[السعر]] -> 230400 | V14: =(sammary[[#This Row],[اجمالى الكمية]]+sammary[[#This Row],[كمية المتبقى امس]]+sammary[[#This Row],[كمية الوارد فروع]])-(sammary[[#This Row],[كمية المبيعات اليومية]]+sammary[[#This Row],[متبقي انتاج اليوم]]) -> #NAME? | W14: =sammary[[#This Row],[فرق الانتاج (المفقود)]]*sammary[[#This Row],[السعر]] -> #NAME? | X14: 168 | Y14: =sammary[[#This Row],[متبقي انتاج اليوم]]*sammary[[#This Row],[السعر]] -> 67200
A15: 8 | B15: 131 | C15: بركر 13 عادي | D15: 300 | E15: 360 | F15: 10 | G15: =Transfer(sammary[[#This Row],[رمز المادة]],transferTable[ر.م.مستورد],transferTable[ر.م.مصدر],transferTable[الكمية]) -> #NAME? | H15: 0 | J15: =SUM(sammary[[#This Row],[شفت المسائي]:[المناقلات]])-SUM(sammary[[#This Row],[نقص الصواني بعد الخبز]:[اكل عمال]])-sammary[[#This Row],[كمية التلف اليومى]] -> #NAME? | K15: =sammary[[#This Row],[اجمالى الكمية]]*sammary[[#This Row],[السعر]] -> #NAME? | L15: ='عداد النازل'!U9 -> #NAME? | M15: =sammary[[#This Row],[نازل]]-sammary[[#This Row],[اجمالى الكمية]] -> #NAME? | O15: =sammary[[#This Row],[كمية المتبقى امس]]*sammary[[#This Row],[السعر]] -> 0 | Q15: =sammary[[#This Row],[كمية الوارد فروع]]*sammary[[#This Row],[السعر]] -> 0 | S15: =sammary[[#This Row],[كمية التلف اليومى]]*sammary[[#This Row],[السعر]] -> 0 | T15: 240 | U15: =sammary[[#This Row],[كمية المبيعات اليومية]]*sammary[[#This Row],[السعر]] -> 72000 | V15: =(sammary[[#This Row],[اجمالى الكمية]]+sammary[[#This Row],[كمية المتبقى امس]]+sammary[[#This Row],[كمية الوارد فروع]])-(sammary[[#This Row],[كمية المبيعات اليومية]]+sammary[[#This Row],[متبقي انتاج اليوم]]) -> #NAME? | W15: =sammary[[#This Row],[فرق الانتاج (المفقود)]]*sammary[[#This Row],[السعر]] -> #NAME? | X15: 46 | Y15: =sammary[[#This Row],[متبقي انتاج اليوم]]*sammary[[#This Row],[السعر]] -> 13800
A16: 9 | B16: 101 | C16: بركر 10 عادي | D16: 250 | E16: 624 | G16: =Transfer(sammary[[#This Row],[رمز المادة]],transferTable[ر.م.مستورد],transferTable[ر.م.مصدر],transferTable[الكمية]) -> #NAME? | H16: 6 | J16: =SUM(sammary[[#This Row],[شفت المسائي]:[المناقلات]])-SUM(sammary[[#This Row],[نقص الصواني بعد الخبز]:[اكل عمال]])-sammary[[#This Row],[كمية التلف اليومى]] -> #NAME? | K16: =sammary[[#This Row],[اجمالى الكمية]]*sammary[[#This Row],[السعر]] -> #NAME? | L16: ='عداد النازل'!U10 -> #NAME? | M16: =sammary[[#This Row],[نازل]]-sammary[[#This Row],[اجمالى الكمية]] -> #NAME? | N16: 468 | O16: =sammary[[#This Row],[كمية المتبقى امس]]*sammary[[#This Row],[السعر]] -> 117000 | Q16: =sammary[[#This Row],[كمية الوارد فروع]]*sammary[[#This Row],[السعر]] -> 0 | S16: =sammary[[#This Row],[كمية التلف اليومى]]*sammary[[#This Row],[السعر]] -> 0 | T16: 970 | U16: =sammary[[#This Row],[كمية المبيعات اليومية]]*sammary[[#This Row],[السعر]] -> 242500 | V16: =(sammary[[#This Row],[اجمالى الكمية]]+sammary[[#This Row],[كمية المتبقى امس]]+sammary[[#This Row],[كمية الوارد فروع]])-(sammary[[#This Row],[كمية المبيعات اليومية]]+sammary[[#This Row],[متبقي انتاج اليوم]]) -> #NAME? | W16: =sammary[[#This Row],[فرق الانتاج (المفقود)]]*sammary[[#This Row],[السعر]] -> #NAME? | X16: 132 | Y16: =sammary[[#This Row],[متبقي انتاج اليوم]]*sammary[[#This Row],[السعر]] -> 33000
A17: 10 | B17: 102 | C17: بركر 10 بطاطا | D17: 450 | E17: 0 | G17: =Transfer(sammary[[#This Row],[رمز المادة]],transferTable[ر.م.مستورد],transferTable[ر.م.مصدر],transferTable[الكمية]) -> #NAME? | H17: 0 | J17: =SUM(sammary[[#This Row],[شفت المسائي]:[المناقلات]])-SUM(sammary[[#This Row],[نقص الصواني بعد الخبز]:[اكل عمال]])-sammary[[#This Row],[كمية التلف اليومى]] -> #NAME? | K17: =sammary[[#This Row],[اجمالى الكمية]]*sammary[[#This Row],[السعر]] -> #NAME? | L17: ='عداد النازل'!U11 -> #NAME? | M17: =sammary[[#This Row],[نازل]]-sammary[[#This Row],[اجمالى الكمية]] -> #NAME? | O17: =sammary[[#This Row],[كمية المتبقى امس]]*sammary[[#This Row],[السعر]] -> 0 | Q17: =sammary[[#This Row],[كمية الوارد فروع]]*sammary[[#This Row],[السعر]] -> 0 | S17: =sammary[[#This Row],[كمية التلف اليومى]]*sammary[[#This Row],[السعر]] -> 0 | T17: 0 | U17: =sammary[[#This Row],[كمية المبيعات اليومية]]*sammary[[#This Row],[السعر]] -> 0 | V17: =(sammary[[#This Row],[اجمالى الكمية]]+sammary[[#This Row],[كمية المتبقى امس]]+sammary[[#This Row],[كمية الوارد فروع]])-(sammary[[#This Row],[كمية المبيعات اليومية]]+sammary[[#This Row],[متبقي انتاج اليوم]]) -> #NAME? | W17: =sammary[[#This Row],[فرق الانتاج (المفقود)]]*sammary[[#This Row],[السعر]] -> #NAME? | Y17: =sammary[[#This Row],[متبقي انتاج اليوم]]*sammary[[#This Row],[السعر]] -> 0
A18: 11 | B18: 666 | C18: مثلث | D18: 250 | E18: 240 | G18: =Transfer(sammary[[#This Row],[رمز المادة]],transferTable[ر.م.مستورد],transferTable[ر.م.مصدر],transferTable[الكمية]) -> #NAME? | H18: 0 | J18: =SUM(sammary[[#This Row],[شفت المسائي]:[المناقلات]])-SUM(sammary[[#This Row],[نقص الصواني بعد الخبز]:[اكل عمال]])-sammary[[#This Row],[كمية التلف اليومى]] -> #NAME? | K18: =sammary[[#This Row],[اجمالى الكمية]]*sammary[[#This Row],[السعر]] -> #NAME? | L18: ='عداد النازل'!U12 -> #NAME? | M18: =sammary[[#This Row],[نازل]]-sammary[[#This Row],[اجمالى الكمية]] -> #NAME? | O18: =sammary[[#This Row],[كمية المتبقى امس]]*sammary[[#This Row],[السعر]] -> 0 | P18: 30 | Q18: =sammary[[#This Row],[كمية الوارد فروع]]*sammary[[#This Row],[السعر]] -> 7500 | S18: =sammary[[#This Row],[كمية التلف اليومى]]*sammary[[#This Row],[السعر]] -> 0 | T18: 270 | U18: =sammary[[#This Row],[كمية المبيعات اليومية]]*sammary[[#This Row],[السعر]] -> 67500 | V18: =(sammary[[#This Row],[اجمالى الكمية]]+sammary[[#This Row],[كمية المتبقى امس]]+sammary[[#This Row],[كمية الوارد فروع]])-(sammary[[#This Row],[كمية المبيعات اليومية]]+sammary[[#This Row],[متبقي انتاج اليوم]]) -> #NAME? | W18: =sammary[[#This Row],[فرق الانتاج (المفقود)]]*sammary[[#This Row],[السعر]] -> #NAME? | Y18: =sammary[[#This Row],[متبقي انتاج اليوم]]*sammary[[#This Row],[السعر]] -> 0
A19: 12 | B19: 261 | C19: فلر 26 عادي | D19: 350 | E19: 6139 | F19: 134 | G19: =Transfer(sammary[[#This Row],[رمز المادة]],transferTable[ر.م.مستورد],transferTable[ر.م.مصدر],transferTable[الكمية]) -> #NAME? | H19: 108 | J19: =SUM(sammary[[#This Row],[شفت المسائي]:[المناقلات]])-SUM(sammary[[#This Row],[نقص الصواني بعد الخبز]:[اكل عمال]])-sammary[[#This Row],[كمية التلف اليومى]] -> #NAME? | K19: =sammary[[#This Row],[اجمالى الكمية]]*sammary[[#This Row],[السعر]] -> #NAME? | L19: ='عداد النازل'!U13 -> #NAME? | M19: =sammary[[#This Row],[نازل]]-sammary[[#This Row],[اجمالى الكمية]] -> #NAME? | O19: =sammary[[#This Row],[كمية المتبقى امس]]*sammary[[#This Row],[السعر]] -> 0 | Q19: =sammary[[#This Row],[كمية الوارد فروع]]*sammary[[#This Row],[السعر]] -> 0 | S19: =sammary[[#This Row],[كمية التلف اليومى]]*sammary[[#This Row],[السعر]] -> 0 | T19: 6128 | U19: =sammary[[#This Row],[كمية المبيعات اليومية]]*sammary[[#This Row],[السعر]] -> 2144800 | V19: =(sammary[[#This Row],[اجمالى الكمية]]+sammary[[#This Row],[كمية المتبقى امس]]+sammary[[#This Row],[كمية الوارد فروع]])-(sammary[[#This Row],[كمية المبيعات اليومية]]+sammary[[#This Row],[متبقي انتاج اليوم]]) -> #NAME? | W19: =sammary[[#This Row],[فرق الانتاج (المفقود)]]*sammary[[#This Row],[السعر]] -> #NAME? | X19: 95 | Y19: =sammary[[#This Row],[متبقي انتاج اليوم]]*sammary[[#This Row],[السعر]] -> 33250
A20: 13 | B20: 262 | C20: فلر 26 بوليش | D20: 400 | E20: 3276 | G20: =Transfer(sammary[[#This Row],[رمز المادة]],transferTable[ر.م.مستورد],transferTable[ر.م.مصدر],transferTable[الكمية]) -> #NAME? | H20: 130 | J20: =SUM(sammary[[#This Row],[شفت المسائي]:[المناقلات]])-SUM(sammary[[#This Row],[نقص الصواني بعد الخبز]:[اكل عمال]])-sammary[[#This Row],[كمية التلف اليومى]] -> #NAME? | K20: =sammary[[#This Row],[اجمالى الكمية]]*sammary[[#This Row],[السعر]] -> #NAME? | L20: ='عداد النازل'!U14 -> #NAME? | M20: =sammary[[#This Row],[نازل]]-sammary[[#This Row],[اجمالى الكمية]] -> #NAME? | O20: =sammary[[#This Row],[كمية المتبقى امس]]*sammary[[#This Row],[السعر]] -> 0 | Q20: =sammary[[#This Row],[كمية الوارد فروع]]*sammary[[#This Row],[السعر]] -> 0 | S20: =sammary[[#This Row],[كمية التلف اليومى]]*sammary[[#This Row],[السعر]] -> 0 | T20: 3044 | U20: =sammary[[#This Row],[كمية المبيعات اليومية]]*sammary[[#This Row],[السعر]] -> 1217600 | V20: =(sammary[[#This Row],[اجمالى الكمية]]+sammary[[#This Row],[كمية المتبقى امس]]+sammary[[#This Row],[كمية الوارد فروع]])-(sammary[[#This Row],[كمية المبيعات اليومية]]+sammary[[#This Row],[متبقي انتاج اليوم]]) -> #NAME? | W20: =sammary[[#This Row],[فرق الانتاج (المفقود)]]*sammary[[#This Row],[السعر]] -> #NAME? | X20: 10 | Y20: =sammary[[#This Row],[متبقي انتاج اليوم]]*sammary[[#This Row],[السعر]] -> 4000
A21: 14 | B21: 263 | C21: فلر 26 سميد | D21: 400 | E21: 1456 | F21: 4 | G21: =Transfer(sammary[[#This Row],[رمز المادة]],transferTable[ر.م.مستورد],transferTable[ر.م.مصدر],transferTable[الكمية]) -> #NAME? | H21: 48 | J21: =SUM(sammary[[#This Row],[شفت المسائي]:[المناقلات]])-SUM(sammary[[#This Row],[نقص الصواني بعد الخبز]:[اكل عمال]])-sammary[[#This Row],[كمية التلف اليومى]] -> #NAME? | K21: =sammary[[#This Row],[اجمالى الكمية]]*sammary[[#This Row],[السعر]] -> #NAME? | L21: ='عداد النازل'!U15 -> #NAME? | M21: =sammary[[#This Row],[نازل]]-sammary[[#This Row],[اجمالى الكمية]] -> #NAME? | O21: =sammary[[#This Row],[كمية المتبقى امس]]*sammary[[#This Row],[السعر]] -> 0 | Q21: =sammary[[#This Row],[كمية الوارد فروع]]*sammary[[#This Row],[السعر]] -> 0 | S21: =sammary[[#This Row],[كمية التلف اليومى]]*sammary[[#This Row],[السعر]] -> 0 | T21: 1416 | U21: =sammary[[#This Row],[كمية المبيعات اليومية]]*sammary[[#This Row],[السعر]] -> 566400 | V21: =(sammary[[#This Row],[اجمالى الكمية]]+sammary[[#This Row],[كمية المتبقى امس]]+sammary[[#This Row],[كمية الوارد فروع]])-(sammary[[#This Row],[كمية المبيعات اليومية]]+sammary[[#This Row],[متبقي انتاج اليوم]]) -> #NAME? | W21: =sammary[[#This Row],[فرق الانتاج (المفقود)]]*sammary[[#This Row],[السعر]] -> #NAME? | X21: 16 | Y21: =sammary[[#This Row],[متبقي انتاج اليوم]]*sammary[[#This Row],[السعر]] -> 6400
A22: 15 | B22: 32 | C22: دبل باسطون | D22: 350 | E22: 3240 | G22: =Transfer(sammary[[#This Row],[رمز المادة]],transferTable[ر.م.مستورد],transferTable[ر.م.مصدر],transferTable[الكمية]) -> #NAME? | H22: 377 | J22: =SUM(sammary[[#This Row],[شفت المسائي]:[المناقلات]])-SUM(sammary[[#This Row],[نقص الصواني بعد الخبز]:[اكل عمال]])-sammary[[#This Row],[كمية التلف اليومى]] -> #NAME? | K22: =sammary[[#This Row],[اجمالى الكمية]]*sammary[[#This Row],[السعر]] -> #NAME? | L22: ='عداد النازل'!U16 -> #NAME? | M22: =sammary[[#This Row],[نازل]]-sammary[[#This Row],[اجمالى الكمية]] -> #NAME? | N22: 175 | O22: =sammary[[#This Row],[كمية المتبقى امس]]*sammary[[#This Row],[السعر]] -> 61250 | Q22: =sammary[[#This Row],[كمية الوارد فروع]]*sammary[[#This Row],[السعر]] -> 0 | S22: =sammary[[#This Row],[كمية التلف اليومى]]*sammary[[#This Row],[السعر]] -> 0 | T22: 2885 | U22: =sammary[[#This Row],[كمية المبيعات اليومية]]*sammary[[#This Row],[السعر]] -> 1009750 | V22: =(sammary[[#This Row],[اجمالى الكمية]]+sammary[[#This Row],[كمية المتبقى امس]]+sammary[[#This Row],[كمية الوارد فروع]])-(sammary[[#This Row],[كمية المبيعات اليومية]]+sammary[[#This Row],[متبقي انتاج اليوم]]) -> #NAME? | W22: =sammary[[#This Row],[فرق الانتاج (المفقود)]]*sammary[[#This Row],[السعر]] -> #NAME? | X22: 123 | Y22: =sammary[[#This Row],[متبقي انتاج اليوم]]*sammary[[#This Row],[السعر]] -> 43050
A23: 16 | B23: 301 | C23: سابوي | D23: 300 | E23: 2920 | F23: 240 | G23: =Transfer(sammary[[#This Row],[رمز المادة]],transferTable[ر.م.مستورد],transferTable[ر.م.مصدر],transferTable[الكمية]) -> #NAME? | H23: 0 | J23: =SUM(sammary[[#This Row],[شفت المسائي]:[المناقلات]])-SUM(sammary[[#This Row],[نقص الصواني بعد الخبز]:[اكل عمال]])-sammary[[#This Row],[كمية التلف اليومى]] -> #NAME? | K23: =sammary[[#This Row],[اجمالى الكمية]]*sammary[[#This Row],[السعر]] -> #NAME? | L23: ='عداد النازل'!U17 -> #NAME? | M23: =sammary[[#This Row],[نازل]]-sammary[[#This Row],[اجمالى الكمية]] -> #NAME? | O23: =sammary[[#This Row],[كمية المتبقى امس]]*sammary[[#This Row],[السعر]] -> 0 | Q23: =sammary[[#This Row],[كمية الوارد فروع]]*sammary[[#This Row],[السعر]] -> 0 | S23: =sammary[[#This Row],[كمية التلف اليومى]]*sammary[[#This Row],[السعر]] -> 0 | T23: 1525 | U23: =sammary[[#This Row],[كمية المبيعات اليومية]]*sammary[[#This Row],[السعر]] -> 457500 | V23: =(sammary[[#This Row],[اجمالى الكمية]]+sammary[[#This Row],[كمية المتبقى امس]]+sammary[[#This Row],[كمية الوارد فروع]])-(sammary[[#This Row],[كمية المبيعات اليومية]]+sammary[[#This Row],[متبقي انتاج اليوم]]) -> #NAME? | W23: =sammary[[#This Row],[فرق الانتاج (المفقود)]]*sammary[[#This Row],[السعر]] -> #NAME? | X23: 6 | Y23: =sammary[[#This Row],[متبقي انتاج اليوم]]*sammary[[#This Row],[السعر]] -> 1800
A24: 17 | B24: 302 | C24: سابوي بوليش | D24: 400 | E24: 0 | G24: =Transfer(sammary[[#This Row],[رمز المادة]],transferTable[ر.م.مستورد],transferTable[ر.م.مصدر],transferTable[الكمية]) -> #NAME? | H24: 5 | J24: =SUM(sammary[[#This Row],[شفت المسائي]:[المناقلات]])-SUM(sammary[[#This Row],[نقص الصواني بعد الخبز]:[اكل عمال]])-sammary[[#This Row],[كمية التلف اليومى]] -> #NAME? | K24: =sammary[[#This Row],[اجمالى الكمية]]*sammary[[#This Row],[السعر]] -> #NAME? | L24: ='عداد النازل'!U18 -> #NAME? | M24: =sammary[[#This Row],[نازل]]-sammary[[#This Row],[اجمالى الكمية]] -> #NAME? | O24: =sammary[[#This Row],[كمية المتبقى امس]]*sammary[[#This Row],[السعر]] -> 0 | P24: 10 | Q24: =sammary[[#This Row],[كمية الوارد فروع]]*sammary[[#This Row],[السعر]] -> 4000 | S24: =sammary[[#This Row],[كمية التلف اليومى]]*sammary[[#This Row],[السعر]] -> 0 | T24: 1614 | U24: =sammary[[#This Row],[كمية المبيعات اليومية]]*sammary[[#This Row],[السعر]] -> 645600 | V24: =(sammary[[#This Row],[اجمالى الكمية]]+sammary[[#This Row],[كمية المتبقى امس]]+sammary[[#This Row],[كمية الوارد فروع]])-(sammary[[#This Row],[كمية المبيعات اليومية]]+sammary[[#This Row],[متبقي انتاج اليوم]]) -> #NAME? | W24: =sammary[[#This Row],[فرق الانتاج (المفقود)]]*sammary[[#This Row],[السعر]] -> #NAME? | X24: 9 | Y24: =sammary[[#This Row],[متبقي انتاج اليوم]]*sammary[[#This Row],[السعر]] -> 3600
A25: 18 | B25: 51 | C25: همام عادي | D25: 250 | E25: 224 | G25: =Transfer(sammary[[#This Row],[رمز المادة]],transferTable[ر.م.مستورد],transferTable[ر.م.مصدر],transferTable[الكمية]) -> #NAME? | H25: 0 | J25: =SUM(sammary[[#This Row],[شفت المسائي]:[المناقلات]])-SUM(sammary[[#This Row],[نقص الصواني بعد الخبز]:[اكل عمال]])-sammary[[#This Row],[كمية التلف اليومى]] -> #NAME? | K25: =sammary[[#This Row],[اجمالى الكمية]]*sammary[[#This Row],[السعر]] -> #NAME? | L25: ='عداد النازل'!U19 -> #NAME? | M25: =sammary[[#This Row],[نازل]]-sammary[[#This Row],[اجمالى الكمية]] -> #NAME? | O25: =sammary[[#This Row],[كمية المتبقى امس]]*sammary[[#This Row],[السعر]] -> 0 | Q25: =sammary[[#This Row],[كمية الوارد فروع]]*sammary[[#This Row],[السعر]] -> 0 | S25: =sammary[[#This Row],[كمية التلف اليومى]]*sammary[[#This Row],[السعر]] -> 0 | T25: 222 | U25: =sammary[[#This Row],[كمية المبيعات اليومية]]*sammary[[#This Row],[السعر]] -> 55500 | V25: =(sammary[[#This Row],[اجمالى الكمية]]+sammary[[#This Row],[كمية المتبقى امس]]+sammary[[#This Row],[كمية الوارد فروع]])-(sammary[[#This Row],[كمية المبيعات اليومية]]+sammary[[#This Row],[متبقي انتاج اليوم]]) -> #NAME? | W25: =sammary[[#This Row],[فرق الانتاج (المفقود)]]*sammary[[#This Row],[السعر]] -> #NAME? | Y25: =sammary[[#This Row],[متبقي انتاج اليوم]]*sammary[[#This Row],[السعر]] -> 0
A26: 19 | B26: 52 | C26: همام مشرح | D26: 400 | E26: 45 | G26: =Transfer(sammary[[#This Row],[رمز المادة]],transferTable[ر.م.مستورد],transferTable[ر.م.مصدر],transferTable[الكمية]) -> #NAME? | H26: 0 | J26: =SUM(sammary[[#This Row],[شفت المسائي]:[المناقلات]])-SUM(sammary[[#This Row],[نقص الصواني بعد الخبز]:[اكل عمال]])-sammary[[#This Row],[كمية التلف اليومى]] -> #NAME? | K26: =sammary[[#This Row],[اجمالى الكمية]]*sammary[[#This Row],[السعر]] -> #NAME? | L26: ='عداد النازل'!U20 -> #NAME? | M26: =sammary[[#This Row],[نازل]]-sammary[[#This Row],[اجمالى الكمية]] -> #NAME? | O26: =sammary[[#This Row],[كمية المتبقى امس]]*sammary[[#This Row],[السعر]] -> 0 | Q26: =sammary[[#This Row],[كمية الوارد فروع]]*sammary[[#This Row],[السعر]] -> 0 | S26: =sammary[[#This Row],[كمية التلف اليومى]]*sammary[[#This Row],[السعر]] -> 0 | T26: 50 | U26: =sammary[[#This Row],[كمية المبيعات اليومية]]*sammary[[#This Row],[السعر]] -> 20000 | V26: =(sammary[[#This Row],[اجمالى الكمية]]+sammary[[#This Row],[كمية المتبقى امس]]+sammary[[#This Row],[كمية الوارد فروع]])-(sammary[[#This Row],[كمية المبيعات اليومية]]+sammary[[#This Row],[متبقي انتاج اليوم]]) -> #NAME? | W26: =sammary[[#This Row],[فرق الانتاج (المفقود)]]*sammary[[#This Row],[السعر]] -> #NAME? | Y26: =sammary[[#This Row],[متبقي انتاج اليوم]]*sammary[[#This Row],[السعر]] -> 0
